---
title: "编译器错误 CS0156"
ms.date: 07/20/2015
ms.prod: .net
ms.technology:
- devlang-csharp
ms.topic: article
f1_keywords:
- CS0156
helpviewer_keywords:
- CS0156
ms.assetid: 32026b1b-bcd7-4464-b63f-3b38c00452a6
caps.latest.revision: 
author: BillWagner
ms.author: wiwagn
ms.openlocfilehash: f755172711f7a09bcbdae518fdcb82aca58cad20
ms.sourcegitcommit: 83dd5ec003e788ccb3e33f3412a7af39ae347646
ms.translationtype: MT
ms.contentlocale: zh-CN
ms.lasthandoff: 03/15/2018
---
# <a name="compiler-error-cs0156"></a><span data-ttu-id="cdf24-102">编译器错误 CS0156</span><span class="sxs-lookup"><span data-stu-id="cdf24-102">Compiler Error CS0156</span></span>
<span data-ttu-id="cdf24-103">在嵌套在最近的封闭 catch 子句内部的 finally 子句内不允许使用不带参数的 throw 语句</span><span class="sxs-lookup"><span data-stu-id="cdf24-103">A throw statement with no arguments is not allowed in a finally clause that is nested inside the nearest enclosing catch clause</span></span>  
  
 <span data-ttu-id="cdf24-104">不带参数的 [throw](../../csharp/language-reference/keywords/throw.md) 语句只能出现在不带任何参数的 **catch** 子句中。</span><span class="sxs-lookup"><span data-stu-id="cdf24-104">A [throw](../../csharp/language-reference/keywords/throw.md) statement with no parameters can only appear in a **catch** clause that takes no parameters.</span></span>  
  
 <span data-ttu-id="cdf24-105">有关详细信息，请参阅[异常处理语句](../../csharp/language-reference/keywords/exception-handling-statements.md)和[异常和异常处理](../../csharp/programming-guide/exceptions/index.md)。</span><span class="sxs-lookup"><span data-stu-id="cdf24-105">For more information, see [Exception Handling Statements](../../csharp/language-reference/keywords/exception-handling-statements.md) and [Exceptions and Exception Handling](../../csharp/programming-guide/exceptions/index.md).</span></span>  
  
 <span data-ttu-id="cdf24-106">下面的示例生成 CS0156：</span><span class="sxs-lookup"><span data-stu-id="cdf24-106">The following sample generates CS0156:</span></span>  
  
```csharp  
// CS0156.cs  
using System;  
  
namespace MyNamespace  
{  
   public class MyClass2 : Exception  
   {  
   }  
  
   public class MyClass  
   {  
      public static void Main()  
      {  
         try  
         {  
            throw;   // CS0156  
         }  
  
         catch(MyClass2)  
         {  
            throw;   // this throw is valid  
         }  
      }  
   }  
}  
```
