---
title: "重试...Catch...Finally 语句 (Visual Basic 中) |Microsoft 文档"
ms.date: 2015-07-20
ms.prod: .net
ms.reviewer: 
ms.suite: 
ms.technology:
- devlang-visual-basic
ms.topic: article
f1_keywords:
- vb.Try...Catch...Finally
- vb.when
- vb.Finally
- vb.Catch
- vb.Try
dev_langs:
- VB
helpviewer_keywords:
- Try...Catch...Finally statements
- Try statement
- try-catch exception handling, Try...Catch...Finally statements
- error handling, while running code
- Try statement, Try...Catch...Finally
- Finally keyword [Visual Basic], Try...Catch...Finally
- Catch statement
- When keyword
- Visual Basic code, handling errors while running
- structured exception handling, Try...Catch...Finally statements
ms.assetid: d6488026-ccb3-42b8-a810-0d97b9d6472b
caps.latest.revision: 69
author: dotnet-bot
ms.author: dotnetcontent
translation.priority.ht:
- cs-cz
- de-de
- es-es
- fr-fr
- it-it
- ja-jp
- ko-kr
- pl-pl
- pt-br
- ru-ru
- tr-tr
- zh-cn
- zh-tw
ms.translationtype: Machine Translation
ms.sourcegitcommit: 9f5b8ebb69c9206ff90b05e748c64d29d82f7a16
ms.openlocfilehash: 590fcd4aa0a6951b63ad12a7d019c09dba1ff38f
ms.contentlocale: zh-cn
ms.lasthandoff: 04/12/2017

---
# <a name="trycatchfinally-statement-visual-basic"></a><span data-ttu-id="1593b-102">Try...Catch...Finally 语句 (Visual Basic)</span><span class="sxs-lookup"><span data-stu-id="1593b-102">Try...Catch...Finally Statement (Visual Basic)</span></span>
<span data-ttu-id="1593b-103">提供了一种方法来处理时可能会发生在给定块中的代码中，仍在运行代码的部分或全部可能错误。</span><span class="sxs-lookup"><span data-stu-id="1593b-103">Provides a way to handle some or all possible errors that may occur in a given block of code, while still running code.</span></span>  
  
## <a name="syntax"></a><span data-ttu-id="1593b-104">语法</span><span class="sxs-lookup"><span data-stu-id="1593b-104">Syntax</span></span>  
  
```  
Try  
    [ tryStatements ]  
    [ Exit Try ]  
[ Catch [ exception [ As type ] ] [ When expression ]  
    [ catchStatements ]  
    [ Exit Try ] ]  
[ Catch ... ]  
[ Finally  
    [ finallyStatements ] ]  
End Try  
```  
  
## <a name="parts"></a><span data-ttu-id="1593b-105">部件</span><span class="sxs-lookup"><span data-stu-id="1593b-105">Parts</span></span>  
  
|<span data-ttu-id="1593b-106">术语</span><span class="sxs-lookup"><span data-stu-id="1593b-106">Term</span></span>|<span data-ttu-id="1593b-107">定义</span><span class="sxs-lookup"><span data-stu-id="1593b-107">Definition</span></span>|  
|---|---|  
|`tryStatements`|<span data-ttu-id="1593b-108">可选。</span><span class="sxs-lookup"><span data-stu-id="1593b-108">Optional.</span></span> <span data-ttu-id="1593b-109">可能发生错误的语句。</span><span class="sxs-lookup"><span data-stu-id="1593b-109">Statement(s) where an error can occur.</span></span> <span data-ttu-id="1593b-110">可以是复合语句。</span><span class="sxs-lookup"><span data-stu-id="1593b-110">Can be a compound statement.</span></span>|  
|`Catch`|<span data-ttu-id="1593b-111">可选。</span><span class="sxs-lookup"><span data-stu-id="1593b-111">Optional.</span></span> <span data-ttu-id="1593b-112">多个`Catch`允许的块。</span><span class="sxs-lookup"><span data-stu-id="1593b-112">Multiple `Catch` blocks permitted.</span></span> <span data-ttu-id="1593b-113">如果在处理时，则会发生异常`Try`阻止时，每个`Catch`文本顺序来确定是否将它与处理该异常，检查语句`exception`表示已引发的异常。</span><span class="sxs-lookup"><span data-stu-id="1593b-113">If an exception occurs when processing the `Try` block, each `Catch` statement is examined in textual order to determine whether it handles the exception, with `exception` representing the exception that has been thrown.</span></span>|  
|`exception`|<span data-ttu-id="1593b-114">可选。</span><span class="sxs-lookup"><span data-stu-id="1593b-114">Optional.</span></span> <span data-ttu-id="1593b-115">任何变量名称。</span><span class="sxs-lookup"><span data-stu-id="1593b-115">Any variable name.</span></span> <span data-ttu-id="1593b-116">`exception` 的初始值是引发的错误的值。</span><span class="sxs-lookup"><span data-stu-id="1593b-116">The initial value of `exception` is the value of the thrown error.</span></span> <span data-ttu-id="1593b-117">与使用`Catch`指定错误捕获。</span><span class="sxs-lookup"><span data-stu-id="1593b-117">Used with `Catch` to specify the error caught.</span></span> <span data-ttu-id="1593b-118">如果省略，`Catch`语句将捕获所有异常。</span><span class="sxs-lookup"><span data-stu-id="1593b-118">If omitted, the `Catch` statement catches any exception.</span></span>|  
|`type`|<span data-ttu-id="1593b-119">可选。</span><span class="sxs-lookup"><span data-stu-id="1593b-119">Optional.</span></span> <span data-ttu-id="1593b-120">指定类筛选器的类型。</span><span class="sxs-lookup"><span data-stu-id="1593b-120">Specifies the type of class filter.</span></span> <span data-ttu-id="1593b-121">如果值`exception`属于指定的类型`type`或派生类型的标识符将成为绑定到的异常对象。</span><span class="sxs-lookup"><span data-stu-id="1593b-121">If the value of `exception` is of the type specified by `type` or of a derived type, the identifier becomes bound to the exception object.</span></span>|  
|`When`|<span data-ttu-id="1593b-122">可选。</span><span class="sxs-lookup"><span data-stu-id="1593b-122">Optional.</span></span> <span data-ttu-id="1593b-123">一个`Catch`语句`When`子句将捕获异常时，才`expression`的计算结果为`True`。</span><span class="sxs-lookup"><span data-stu-id="1593b-123">A `Catch` statement with a `When` clause catches exceptions only when `expression` evaluates to `True`.</span></span> <span data-ttu-id="1593b-124">一个`When`子句只在检查的类型的异常之后, 应用和`expression`可能引用表示异常的标识符。</span><span class="sxs-lookup"><span data-stu-id="1593b-124">A `When` clause is applied only after checking the type of the exception, and `expression` may refer to the identifier representing the exception.</span></span>|  
|`expression`|<span data-ttu-id="1593b-125">可选。</span><span class="sxs-lookup"><span data-stu-id="1593b-125">Optional.</span></span> <span data-ttu-id="1593b-126">必须是隐式转换为`Boolean`。</span><span class="sxs-lookup"><span data-stu-id="1593b-126">Must be implicitly convertible to `Boolean`.</span></span> <span data-ttu-id="1593b-127">描述泛型的筛选器的任何表达式。</span><span class="sxs-lookup"><span data-stu-id="1593b-127">Any expression that describes a generic filter.</span></span> <span data-ttu-id="1593b-128">通常用于筛选的错误号。</span><span class="sxs-lookup"><span data-stu-id="1593b-128">Typically used to filter by error number.</span></span> <span data-ttu-id="1593b-129">与使用`When`关键字来指定捕获错误时的情况。</span><span class="sxs-lookup"><span data-stu-id="1593b-129">Used with `When` keyword to specify circumstances under which the error is caught.</span></span>|  
|`catchStatements`|<span data-ttu-id="1593b-130">可选。</span><span class="sxs-lookup"><span data-stu-id="1593b-130">Optional.</span></span> <span data-ttu-id="1593b-131">语句来处理在关联中发生的错误`Try`块。</span><span class="sxs-lookup"><span data-stu-id="1593b-131">Statement(s) to handle errors that occur in the associated `Try` block.</span></span> <span data-ttu-id="1593b-132">可以是复合语句。</span><span class="sxs-lookup"><span data-stu-id="1593b-132">Can be a compound statement.</span></span>|  
|`Exit Try`|<span data-ttu-id="1593b-133">可选。</span><span class="sxs-lookup"><span data-stu-id="1593b-133">Optional.</span></span> <span data-ttu-id="1593b-134">跳出关键字`Try...Catch...Finally`结构。</span><span class="sxs-lookup"><span data-stu-id="1593b-134">Keyword that breaks out of the `Try...Catch...Finally` structure.</span></span> <span data-ttu-id="1593b-135">紧随的代码处继续执行`End Try`语句。</span><span class="sxs-lookup"><span data-stu-id="1593b-135">Execution resumes with the code immediately following the `End Try` statement.</span></span> <span data-ttu-id="1593b-136">`Finally`仍将继续执行语句。</span><span class="sxs-lookup"><span data-stu-id="1593b-136">The `Finally` statement will still be executed.</span></span> <span data-ttu-id="1593b-137">中不允许使用`Finally`块。</span><span class="sxs-lookup"><span data-stu-id="1593b-137">Not allowed in `Finally` blocks.</span></span>|  
|`Finally`|<span data-ttu-id="1593b-138">可选。</span><span class="sxs-lookup"><span data-stu-id="1593b-138">Optional.</span></span> <span data-ttu-id="1593b-139">一个`Finally`当执行离开的任何部分，则始终执行块`Try...Catch`语句。</span><span class="sxs-lookup"><span data-stu-id="1593b-139">A `Finally` block is always executed when execution leaves any part of the `Try...Catch` statement.</span></span>|  
|`finallyStatements`|<span data-ttu-id="1593b-140">可选。</span><span class="sxs-lookup"><span data-stu-id="1593b-140">Optional.</span></span> <span data-ttu-id="1593b-141">所有其他错误处理发生后执行的语句。</span><span class="sxs-lookup"><span data-stu-id="1593b-141">Statement(s) that are executed after all other error processing has occurred.</span></span>|  
|`End Try`|<span data-ttu-id="1593b-142">终止`Try...Catch...Finally`结构。</span><span class="sxs-lookup"><span data-stu-id="1593b-142">Terminates the `Try...Catch...Finally` structure.</span></span>|  
  
## <a name="remarks"></a><span data-ttu-id="1593b-143">备注</span><span class="sxs-lookup"><span data-stu-id="1593b-143">Remarks</span></span>  
 <span data-ttu-id="1593b-144">如果希望特定异常可能会出现在特定的代码部分的过程，请将代码放入`Try`块又使用`Catch`块来保留控制处理该异常发生时。</span><span class="sxs-lookup"><span data-stu-id="1593b-144">If you expect that a particular exception might occur during a particular section of code, put the code in a `Try` block and use a `Catch` block to retain control and handle the exception if it occurs.</span></span>  
  
 <span data-ttu-id="1593b-145">一个`Try…Catch`语句组成`Try`块后跟一个或多个`Catch`子句，指定的各种异常处理程序。</span><span class="sxs-lookup"><span data-stu-id="1593b-145">A `Try…Catch` statement consists of a `Try` block followed by one or more `Catch` clauses, which specify handlers for various exceptions.</span></span> <span data-ttu-id="1593b-146">引发异常时`Try`块中，[!INCLUDE[vbprvb](../../../csharp/programming-guide/concepts/linq/includes/vbprvb_md.md)]寻找`Catch`处理该异常的语句。</span><span class="sxs-lookup"><span data-stu-id="1593b-146">When an exception is thrown in a `Try` block, [!INCLUDE[vbprvb](../../../csharp/programming-guide/concepts/linq/includes/vbprvb_md.md)] looks for the `Catch` statement that handles the exception.</span></span> <span data-ttu-id="1593b-147">如果匹配`Catch`找不到语句，[!INCLUDE[vbprvb](../../../csharp/programming-guide/concepts/linq/includes/vbprvb_md.md)]检查调用当前方法，然后会遍历调用堆栈的方法。</span><span class="sxs-lookup"><span data-stu-id="1593b-147">If a matching `Catch` statement is not found, [!INCLUDE[vbprvb](../../../csharp/programming-guide/concepts/linq/includes/vbprvb_md.md)] examines the method that called the current method, and so on up the call stack.</span></span> <span data-ttu-id="1593b-148">如果不是`Catch`找到该块，[!INCLUDE[vbprvb](../../../csharp/programming-guide/concepts/linq/includes/vbprvb_md.md)]向用户显示一条未处理的异常消息并停止执行该程序。</span><span class="sxs-lookup"><span data-stu-id="1593b-148">If no `Catch` block is found, [!INCLUDE[vbprvb](../../../csharp/programming-guide/concepts/linq/includes/vbprvb_md.md)] displays an unhandled exception message to the user and stops execution of the program.</span></span>  
  
 <span data-ttu-id="1593b-149">您可以使用多个`Catch`中的语句`Try…Catch`语句。</span><span class="sxs-lookup"><span data-stu-id="1593b-149">You can use more than one `Catch` statement in a `Try…Catch` statement.</span></span> <span data-ttu-id="1593b-150">如果执行此操作的顺序`Catch`子句很重要，因为它们会按顺序检查。</span><span class="sxs-lookup"><span data-stu-id="1593b-150">If you do this, the order of the `Catch` clauses is significant because they are examined in order.</span></span> <span data-ttu-id="1593b-151">在使用更笼统的子句之前获取特定性更强的异常。</span><span class="sxs-lookup"><span data-stu-id="1593b-151">Catch the more specific exceptions before the less specific ones.</span></span>  
  
 <span data-ttu-id="1593b-152">以下`Catch`语句条件将具体性，并将捕获所有异常派生自<xref:System.Exception>类。</xref:System.Exception></span><span class="sxs-lookup"><span data-stu-id="1593b-152">The following `Catch` statement conditions are the least specific, and will catch all exceptions that derive from the <xref:System.Exception> class.</span></span> <span data-ttu-id="1593b-153">通常应作为上一次将这些变体之一`Catch`阻止入`Try...Catch...Finally`后捕获您期望的所有特定异常的结构。</span><span class="sxs-lookup"><span data-stu-id="1593b-153">You should ordinarily use one of these variations as the last `Catch` block in the `Try...Catch...Finally` structure, after catching all the specific exceptions you expect.</span></span> <span data-ttu-id="1593b-154">控制流可以永远不能到达`Catch`遵循以下任一这些变体的块。</span><span class="sxs-lookup"><span data-stu-id="1593b-154">Control flow can never reach a `Catch` block that follows either of these variations.</span></span>  
  
-   <span data-ttu-id="1593b-155">`type`是`Exception`，例如︰`Catch ex As Exception`</span><span class="sxs-lookup"><span data-stu-id="1593b-155">The `type` is `Exception`, for example: `Catch ex As Exception`</span></span>  
  
-   <span data-ttu-id="1593b-156">该语句没有`exception`变量，例如︰`Catch`</span><span class="sxs-lookup"><span data-stu-id="1593b-156">The statement has no `exception` variable, for example: `Catch`</span></span>  
  
 <span data-ttu-id="1593b-157">当`Try…Catch…Finally`语句嵌套在另一个`Try`块中，[!INCLUDE[vbprvb](../../../csharp/programming-guide/concepts/linq/includes/vbprvb_md.md)]首先检查每个`Catch`语句中使用最内层`Try`块。</span><span class="sxs-lookup"><span data-stu-id="1593b-157">When a `Try…Catch…Finally` statement is nested in another `Try` block, [!INCLUDE[vbprvb](../../../csharp/programming-guide/concepts/linq/includes/vbprvb_md.md)] first examines each `Catch` statement in the innermost `Try` block.</span></span> <span data-ttu-id="1593b-158">如果没有匹配`Catch`找到语句，则继续搜索`Catch`语句的外部`Try…Catch…Finally`块。</span><span class="sxs-lookup"><span data-stu-id="1593b-158">If no matching `Catch` statement is found, the search proceeds to the `Catch` statements of the outer `Try…Catch…Finally` block.</span></span>  
  
 <span data-ttu-id="1593b-159">从本地变量`Try`块中均不提供`Catch`进行阻止，因为它们是单独的块。</span><span class="sxs-lookup"><span data-stu-id="1593b-159">Local variables from a `Try` block are not available in a `Catch` block because they are separate blocks.</span></span> <span data-ttu-id="1593b-160">如果您想要在多个块中使用变量，之外声明该变量`Try...Catch...Finally`结构。</span><span class="sxs-lookup"><span data-stu-id="1593b-160">If you want to use a variable in more than one block, declare the variable outside the `Try...Catch...Finally` structure.</span></span>  
  
> [!TIP]
>  <span data-ttu-id="1593b-161">`Try…Catch…Finally`语句是可用作 IntelliSense 代码段。</span><span class="sxs-lookup"><span data-stu-id="1593b-161">The `Try…Catch…Finally` statement is available as an IntelliSense code snippet.</span></span> <span data-ttu-id="1593b-162">在代码段管理器中，展开**代码模式-如果，对于每个，Try Catch 属性，等**，然后**错误处理 （异常）**。</span><span class="sxs-lookup"><span data-stu-id="1593b-162">In the Code Snippets Manager, expand **Code Patterns - If, For Each, Try Catch, Property, etc**, and then **Error Handling (Exceptions)**.</span></span> <span data-ttu-id="1593b-163">有关详细信息，请参阅[代码片段](https://docs.microsoft.com/visualstudio/ide/code-snippets)。</span><span class="sxs-lookup"><span data-stu-id="1593b-163">For more information, see [Code Snippets](https://docs.microsoft.com/visualstudio/ide/code-snippets).</span></span>  
  
## <a name="finally-block"></a><span data-ttu-id="1593b-164">Finally 块</span><span class="sxs-lookup"><span data-stu-id="1593b-164">Finally Block</span></span>  
 <span data-ttu-id="1593b-165">如果您有一个或多个语句在退出之前必须运行`Try`结构，请使用`Finally`块。</span><span class="sxs-lookup"><span data-stu-id="1593b-165">If you have one or more statements that must run before you exit the `Try` structure, use a `Finally` block.</span></span> <span data-ttu-id="1593b-166">控制权将传递给`Finally`阻止它传递出之前`Try…Catch`结构。</span><span class="sxs-lookup"><span data-stu-id="1593b-166">Control passes to the `Finally` block just before it passes out of the `Try…Catch` structure.</span></span> <span data-ttu-id="1593b-167">即使内任何位置发生异常，这是如此`Try`结构。</span><span class="sxs-lookup"><span data-stu-id="1593b-167">This is true even if an exception occurs anywhere inside the `Try` structure.</span></span>  
  
 <span data-ttu-id="1593b-168">一个`Finally`块可用于运行任何代码必须执行，即使出现异常。</span><span class="sxs-lookup"><span data-stu-id="1593b-168">A `Finally` block is useful for running any code that must execute even if there is an exception.</span></span> <span data-ttu-id="1593b-169">控制权将传递给`Finally`块而不考虑如何`Try...Catch`阻止退出。</span><span class="sxs-lookup"><span data-stu-id="1593b-169">Control is passed to the `Finally` block regardless of how the `Try...Catch` block exits.</span></span>  
  
 <span data-ttu-id="1593b-170">中的代码`Finally`阻止运行，即使您的代码遇到`Return`中的语句`Try`或`Catch`块。</span><span class="sxs-lookup"><span data-stu-id="1593b-170">The code in a `Finally` block runs even if your code encounters a `Return` statement in a `Try` or `Catch` block.</span></span> <span data-ttu-id="1593b-171">控件未通过从`Try`或`Catch`阻止对相应`Finally`阻止在以下情况︰</span><span class="sxs-lookup"><span data-stu-id="1593b-171">Control does not pass from a `Try` or `Catch` block to the corresponding `Finally` block in the following cases:</span></span>  
  
-   <span data-ttu-id="1593b-172">[End 语句](../../../visual-basic/language-reference/statements/end-statement.md)中遇到`Try`或`Catch`块。</span><span class="sxs-lookup"><span data-stu-id="1593b-172">An [End Statement](../../../visual-basic/language-reference/statements/end-statement.md) is encountered in the `Try` or `Catch` block.</span></span>  
  
-   <span data-ttu-id="1593b-173">一个<xref:System.StackOverflowException>中引发`Try`或`Catch`块。</xref:System.StackOverflowException></span><span class="sxs-lookup"><span data-stu-id="1593b-173">A <xref:System.StackOverflowException> is thrown in the `Try` or `Catch` block.</span></span>  
  
 <span data-ttu-id="1593b-174">不能用来显式将执行传输到`Finally`块。</span><span class="sxs-lookup"><span data-stu-id="1593b-174">It is not valid to explicitly transfer execution into a `Finally` block.</span></span> <span data-ttu-id="1593b-175">将执行共转`Finally`块不是有效的除非通过异常。</span><span class="sxs-lookup"><span data-stu-id="1593b-175">Transferring execution out of a `Finally` block is not valid, except through an exception.</span></span>  
  
 <span data-ttu-id="1593b-176">如果`Try`语句未包含至少一个`Catch`块中，它必须包含`Finally`块。</span><span class="sxs-lookup"><span data-stu-id="1593b-176">If a `Try` statement does not contain at least one `Catch` block, it must contain a `Finally` block.</span></span>  
  
> [!TIP]
>  <span data-ttu-id="1593b-177">如果不需要捕获特定异常，`Using`语句的行为类似`Try…Finally`块中，且保证会处置的资源，而不考虑如何退出块。</span><span class="sxs-lookup"><span data-stu-id="1593b-177">If you do not have to catch specific exceptions, the `Using` statement behaves like a `Try…Finally` block, and guarantees disposal of the resources, regardless of how you exit the block.</span></span> <span data-ttu-id="1593b-178">这是即使使用未经处理的异常，则返回 true。</span><span class="sxs-lookup"><span data-stu-id="1593b-178">This is true even with an unhandled exception.</span></span> <span data-ttu-id="1593b-179">有关详细信息，请参阅[Using 语句](../../../visual-basic/language-reference/statements/using-statement.md)。</span><span class="sxs-lookup"><span data-stu-id="1593b-179">For more information, see [Using Statement](../../../visual-basic/language-reference/statements/using-statement.md).</span></span>  
  
## <a name="exception-argument"></a><span data-ttu-id="1593b-180">异常参数</span><span class="sxs-lookup"><span data-stu-id="1593b-180">Exception Argument</span></span>  
 <span data-ttu-id="1593b-181">`Catch`块`exception`参数是实例<xref:System.Exception>类或派生自类`Exception`类</xref:System.Exception></span><span class="sxs-lookup"><span data-stu-id="1593b-181">The `Catch` block `exception` argument is an instance of the <xref:System.Exception> class or a class that derives from the `Exception` class.</span></span> <span data-ttu-id="1593b-182">`Exception`类实例对应于中出现的错误`Try`块。</span><span class="sxs-lookup"><span data-stu-id="1593b-182">The `Exception` class instance corresponds to the error that occurred in the `Try` block.</span></span>  
  
 <span data-ttu-id="1593b-183">属性的`Exception`对象帮助以确定原因和处理的异常的位置。</span><span class="sxs-lookup"><span data-stu-id="1593b-183">The properties of the `Exception` object help to identify the cause and location of an exception.</span></span> <span data-ttu-id="1593b-184">例如，<xref:System.Exception.StackTrace%2A>属性列出导致异常，帮助您找到代码中发生错误的调用的方法。</xref:System.Exception.StackTrace%2A></span><span class="sxs-lookup"><span data-stu-id="1593b-184">For example, the <xref:System.Exception.StackTrace%2A> property lists the called methods that led to the exception, helping you find where the error occurred in the code.</span></span> <span data-ttu-id="1593b-185"><xref:System.Exception.Message%2A>返回一条描述异常的消息。</xref:System.Exception.Message%2A></span><span class="sxs-lookup"><span data-stu-id="1593b-185"><xref:System.Exception.Message%2A> returns a message that describes the exception.</span></span> <span data-ttu-id="1593b-186"><xref:System.Exception.HelpLink%2A>返回指向相关联的帮助文件的链接。</xref:System.Exception.HelpLink%2A></span><span class="sxs-lookup"><span data-stu-id="1593b-186"><xref:System.Exception.HelpLink%2A> returns a link to an associated Help file.</span></span> <span data-ttu-id="1593b-187"><xref:System.Exception.InnerException%2A>返回`Exception`导致当前异常，或它的对象返回`Nothing`如果没有原始`Exception`。</xref:System.Exception.InnerException%2A></span><span class="sxs-lookup"><span data-stu-id="1593b-187"><xref:System.Exception.InnerException%2A> returns the `Exception` object that caused the current exception, or it returns `Nothing` if there is no original `Exception`.</span></span>  
  
## <a name="considerations-when-using-a-trycatch-statement"></a><span data-ttu-id="1593b-188">使用一试时的注意事项...Catch 语句</span><span class="sxs-lookup"><span data-stu-id="1593b-188">Considerations When Using a Try…Catch Statement</span></span>  
 <span data-ttu-id="1593b-189">使用`Try…Catch`语句只是为了发出信号不寻常或意外程序事件的发生次数。</span><span class="sxs-lookup"><span data-stu-id="1593b-189">Use a `Try…Catch` statement only to signal the occurrence of unusual or unanticipated program events.</span></span> <span data-ttu-id="1593b-190">此问题的原因包括︰</span><span class="sxs-lookup"><span data-stu-id="1593b-190">Reasons for this include the following:</span></span>  
  
-   <span data-ttu-id="1593b-191">在运行时捕获的异常创建额外系统开销，并可能需要比预检查以避免异常慢。</span><span class="sxs-lookup"><span data-stu-id="1593b-191">Catching exceptions at runtime creates additional overhead, and is likely to be slower than pre-checking to avoid exceptions.</span></span>  
  
-   <span data-ttu-id="1593b-192">如果`Catch`块不能正确处理，该异常可能不会正确报告给用户。</span><span class="sxs-lookup"><span data-stu-id="1593b-192">If a `Catch` block is not handled correctly, the exception might not be reported correctly to users.</span></span>  
  
-   <span data-ttu-id="1593b-193">异常处理会使程序更复杂。</span><span class="sxs-lookup"><span data-stu-id="1593b-193">Exception handling makes a program more complex.</span></span>  
  
 <span data-ttu-id="1593b-194">您并不总是需要`Try…Catch`语句，以检查可能会发生事件的条件。</span><span class="sxs-lookup"><span data-stu-id="1593b-194">You do not always need a `Try…Catch` statement to check for a condition that is likely to occur.</span></span> <span data-ttu-id="1593b-195">以下示例检查文件是否存在便会尝试将其打开。</span><span class="sxs-lookup"><span data-stu-id="1593b-195">The following example checks whether a file exists before trying to open it.</span></span> <span data-ttu-id="1593b-196">这减少了用于捕获引发的异常需要<xref:System.IO.File.OpenText%2A>方法。</xref:System.IO.File.OpenText%2A></span><span class="sxs-lookup"><span data-stu-id="1593b-196">This reduces the need for catching an exception thrown by the <xref:System.IO.File.OpenText%2A> method.</span></span>  
  
 <span data-ttu-id="1593b-197">[!code-vb[VbVbalrStatements #&94;](../../../visual-basic/language-reference/error-messages/codesnippet/VisualBasic/try-catch-finally-statement_1.vb)]</span><span class="sxs-lookup"><span data-stu-id="1593b-197">[!code-vb[VbVbalrStatements#94](../../../visual-basic/language-reference/error-messages/codesnippet/VisualBasic/try-catch-finally-statement_1.vb)]</span></span>  
  
 <span data-ttu-id="1593b-198">确保在该代码`Catch`块可以将异常正确报告给用户，无论是通过线程安全日志记录还是相应的消息。</span><span class="sxs-lookup"><span data-stu-id="1593b-198">Ensure that code in `Catch` blocks can properly report exceptions to users, whether through thread-safe logging or appropriate messages.</span></span> <span data-ttu-id="1593b-199">否则，异常可能仍是未知的。</span><span class="sxs-lookup"><span data-stu-id="1593b-199">Otherwise, exceptions might remain unknown.</span></span>  
  
## <a name="async-methods"></a><span data-ttu-id="1593b-200">异步方法</span><span class="sxs-lookup"><span data-stu-id="1593b-200">Async Methods</span></span>  
 <span data-ttu-id="1593b-201">如果将标记的方法，其[异步](../../../visual-basic/language-reference/modifiers/async.md)修饰符，您可以使用[Await](../../../visual-basic/language-reference/operators/await-operator.md)方法中的运算符。</span><span class="sxs-lookup"><span data-stu-id="1593b-201">If you mark a method with the [Async](../../../visual-basic/language-reference/modifiers/async.md) modifier, you can use the [Await](../../../visual-basic/language-reference/operators/await-operator.md) operator in the method.</span></span> <span data-ttu-id="1593b-202">具有的语句`Await`运算符暂停执行方法，直到所等待的任务完成。</span><span class="sxs-lookup"><span data-stu-id="1593b-202">A statement with the `Await` operator suspends execution of the method until the awaited task completes.</span></span> <span data-ttu-id="1593b-203">任务表示正在进行的工作。</span><span class="sxs-lookup"><span data-stu-id="1593b-203">The task represents ongoing work.</span></span> <span data-ttu-id="1593b-204">当与相关联的任务`Await`运算符完成后，执行将继续在同一方法中。</span><span class="sxs-lookup"><span data-stu-id="1593b-204">When the task that's associated with the `Await` operator finishes, execution resumes in the same method.</span></span> <span data-ttu-id="1593b-205">有关详细信息，请参阅[异步程序中的控制流](../../../visual-basic/programming-guide/concepts/async/control-flow-in-async-programs.md)。</span><span class="sxs-lookup"><span data-stu-id="1593b-205">For more information, see [Control Flow in Async Programs](../../../visual-basic/programming-guide/concepts/async/control-flow-in-async-programs.md).</span></span>  
  
 <span data-ttu-id="1593b-206">任务返回的异步方法最终可能处于错误状态，指示它完成由于未经处理的异常。</span><span class="sxs-lookup"><span data-stu-id="1593b-206">A task returned by an Async method may end in a faulted state, indicating that it completed due to an unhandled exception.</span></span> <span data-ttu-id="1593b-207">一项任务可能还会已取消状态，这会导致`OperationCanceledException`引发外 await 表达式。</span><span class="sxs-lookup"><span data-stu-id="1593b-207">A task may also end in a canceled state, which results in an `OperationCanceledException` being thrown out of the await expression.</span></span> <span data-ttu-id="1593b-208">若要捕获其中任何一种异常，将放置`Await`中的任务相关联的表达式`Try`块，并捕获该异常在`Catch`块。</span><span class="sxs-lookup"><span data-stu-id="1593b-208">To catch either type of exception, place the `Await` expression that's associated with the task in a `Try` block, and catch the exception in the `Catch` block.</span></span> <span data-ttu-id="1593b-209">在本主题后面提供了示例。</span><span class="sxs-lookup"><span data-stu-id="1593b-209">An example is provided later in this topic.</span></span>  
  
 <span data-ttu-id="1593b-210">一项任务可能处于错误状态，因为多个异常的负责其处理故障。</span><span class="sxs-lookup"><span data-stu-id="1593b-210">A task can be in a faulted state because multiple exceptions were responsible for its faulting.</span></span> <span data-ttu-id="1593b-211">例如，任务可能是到<xref:System.Threading.Tasks.Task.WhenAll%2A?displayProperty=fullName>。</xref:System.Threading.Tasks.Task.WhenAll%2A?displayProperty=fullName>调用的结果</span><span class="sxs-lookup"><span data-stu-id="1593b-211">For example, the task might be the result of a call to <xref:System.Threading.Tasks.Task.WhenAll%2A?displayProperty=fullName>.</span></span> <span data-ttu-id="1593b-212">当等待此任务时，捕获的异常都只有一个例外，而您无法预测将捕获的异常。</span><span class="sxs-lookup"><span data-stu-id="1593b-212">When you await such a task, the caught exception is only one of the exceptions, and you can't predict which exception will be caught.</span></span> <span data-ttu-id="1593b-213">在本主题后面提供了示例。</span><span class="sxs-lookup"><span data-stu-id="1593b-213">An example is provided later in this topic.</span></span>  
  
 <span data-ttu-id="1593b-214">`Await`表达式不能包含在内`Catch`块或`Finally`块。</span><span class="sxs-lookup"><span data-stu-id="1593b-214">An `Await` expression can't be inside a `Catch` block or `Finally` block.</span></span>  
  
## <a name="iterators"></a><span data-ttu-id="1593b-215">迭代器</span><span class="sxs-lookup"><span data-stu-id="1593b-215">Iterators</span></span>  
 <span data-ttu-id="1593b-216">迭代器函数或`Get`访问器在集合上执行自定义的迭代。</span><span class="sxs-lookup"><span data-stu-id="1593b-216">An iterator function or `Get` accessor performs a custom iteration over a collection.</span></span> <span data-ttu-id="1593b-217">迭代器使用[产生](../../../visual-basic/language-reference/statements/yield-statement.md)语句可返回一次该集合的每个元素。</span><span class="sxs-lookup"><span data-stu-id="1593b-217">An iterator uses a [Yield](../../../visual-basic/language-reference/statements/yield-statement.md) statement to return each element of the collection one at a time.</span></span> <span data-ttu-id="1593b-218">通过使用调用迭代器函数[为每个...下一条语句](../../../visual-basic/language-reference/statements/for-each-next-statement.md)。</span><span class="sxs-lookup"><span data-stu-id="1593b-218">You call an iterator function by using a [For Each...Next Statement](../../../visual-basic/language-reference/statements/for-each-next-statement.md).</span></span>  
  
 <span data-ttu-id="1593b-219">一个`Yield`语句可以是内部`Try`块。</span><span class="sxs-lookup"><span data-stu-id="1593b-219">A `Yield` statement can be inside a `Try` block.</span></span> <span data-ttu-id="1593b-220">一个`Try`包含块`Yield`语句可以有`Catch`阻止，并且也能`Finally`块。</span><span class="sxs-lookup"><span data-stu-id="1593b-220">A `Try` block that contains a `Yield` statement can have `Catch` blocks, and can have a `Finally` block.</span></span> <span data-ttu-id="1593b-221">请参阅的"重试块在 Visual Basic"部分[迭代器](http://msdn.microsoft.com/library/f45331db-d595-46ec-9142-551d3d1eb1a7)有关的示例。</span><span class="sxs-lookup"><span data-stu-id="1593b-221">See the "Try Blocks in Visual Basic" section of [Iterators](http://msdn.microsoft.com/library/f45331db-d595-46ec-9142-551d3d1eb1a7) for an example.</span></span>  
  
 <span data-ttu-id="1593b-222">一个`Yield`语句不能包含在内`Catch`块或`Finally`块。</span><span class="sxs-lookup"><span data-stu-id="1593b-222">A `Yield` statement cannot be inside a `Catch` block or a `Finally` block.</span></span>  
  
 <span data-ttu-id="1593b-223">如果`For Each`主体 （在之外的迭代器函数） 引发了异常，`Catch`未执行迭代器函数中的块，但`Finally`执行迭代器函数中的块。</span><span class="sxs-lookup"><span data-stu-id="1593b-223">If the `For Each` body (outside of the iterator function) throws an exception, a `Catch` block in the iterator function is not executed, but a `Finally` block in the iterator function is executed.</span></span> <span data-ttu-id="1593b-224">一个`Catch`迭代器函数内部的块将捕获在迭代器函数内部发生的异常。</span><span class="sxs-lookup"><span data-stu-id="1593b-224">A `Catch` block inside an iterator function catches only exceptions that occur inside the iterator function.</span></span>  
  
## <a name="partial-trust-situations"></a><span data-ttu-id="1593b-225">部分信任的情况下</span><span class="sxs-lookup"><span data-stu-id="1593b-225">Partial-Trust Situations</span></span>  
 <span data-ttu-id="1593b-226">在部分信任情况下，例如在网络共享上托管的应用程序`Try...Catch...Finally`不捕获调用包含调用该方法之前发生的安全异常。</span><span class="sxs-lookup"><span data-stu-id="1593b-226">In partial-trust situations, such as an application hosted on a network share, `Try...Catch...Finally` does not catch security exceptions that occur before the method that contains the call is invoked.</span></span> <span data-ttu-id="1593b-227">以下示例中，则将其置于服务器共享并运行在这里时, 产生错误"System.Security.SecurityException︰ 请求失败。"</span><span class="sxs-lookup"><span data-stu-id="1593b-227">The following example, when you put it on a server share and run from there, produces the error "System.Security.SecurityException: Request Failed."</span></span> <span data-ttu-id="1593b-228">有关安全异常的详细信息，请参阅<xref:System.Security.SecurityException>类。</xref:System.Security.SecurityException></span><span class="sxs-lookup"><span data-stu-id="1593b-228">For more information about security exceptions, see the <xref:System.Security.SecurityException> class.</span></span>  
  
 <span data-ttu-id="1593b-229">[!code-vb[VbVbalrStatements #&85;](../../../visual-basic/language-reference/error-messages/codesnippet/VisualBasic/try-catch-finally-statement_2.vb)]</span><span class="sxs-lookup"><span data-stu-id="1593b-229">[!code-vb[VbVbalrStatements#85](../../../visual-basic/language-reference/error-messages/codesnippet/VisualBasic/try-catch-finally-statement_2.vb)]</span></span>  
  
 <span data-ttu-id="1593b-230">在此类的部分信任情况下，您必须将`Process.Start`位于一个单独的语句`Sub`。</span><span class="sxs-lookup"><span data-stu-id="1593b-230">In such a partial-trust situation, you have to put the `Process.Start` statement in a separate `Sub`.</span></span> <span data-ttu-id="1593b-231">首次调用`Sub`将失败。</span><span class="sxs-lookup"><span data-stu-id="1593b-231">The initial call to the `Sub` will fail.</span></span> <span data-ttu-id="1593b-232">这使`Try...Catch`可以捕捉到它之前`Sub`，其中包含`Process.Start`已启动并产生安全异常。</span><span class="sxs-lookup"><span data-stu-id="1593b-232">This enables `Try...Catch` to catch it before the `Sub` that contains `Process.Start` is started and the security exception produced.</span></span>  
  
## <a name="example"></a><span data-ttu-id="1593b-233">示例</span><span class="sxs-lookup"><span data-stu-id="1593b-233">Example</span></span>  
 <span data-ttu-id="1593b-234">下面的示例演示的结构`Try...Catch...Finally`语句。</span><span class="sxs-lookup"><span data-stu-id="1593b-234">The following example illustrates the structure of the `Try...Catch...Finally` statement.</span></span>  
  
 <span data-ttu-id="1593b-235">[!code-vb[VbVbalrStatements #&86;](../../../visual-basic/language-reference/error-messages/codesnippet/VisualBasic/try-catch-finally-statement_3.vb)]</span><span class="sxs-lookup"><span data-stu-id="1593b-235">[!code-vb[VbVbalrStatements#86](../../../visual-basic/language-reference/error-messages/codesnippet/VisualBasic/try-catch-finally-statement_3.vb)]</span></span>  
  
## <a name="example"></a><span data-ttu-id="1593b-236">示例</span><span class="sxs-lookup"><span data-stu-id="1593b-236">Example</span></span>  
 <span data-ttu-id="1593b-237">在下面的示例中，`CreateException`方法抛出异常`NullReferenceException`。</span><span class="sxs-lookup"><span data-stu-id="1593b-237">In the following example, the `CreateException` method throws a `NullReferenceException`.</span></span> <span data-ttu-id="1593b-238">生成异常的代码不在`Try`块。</span><span class="sxs-lookup"><span data-stu-id="1593b-238">The code that generates the exception is not in a `Try` block.</span></span> <span data-ttu-id="1593b-239">因此，`CreateException`方法未处理异常。</span><span class="sxs-lookup"><span data-stu-id="1593b-239">Therefore, the `CreateException` method does not handle the exception.</span></span> <span data-ttu-id="1593b-240">`RunSample`方法未处理该异常，因为调用`CreateException`方法正在`Try`块。</span><span class="sxs-lookup"><span data-stu-id="1593b-240">The `RunSample` method does handle the exception because the call to the `CreateException` method is in a `Try` block.</span></span>  
  
 <span data-ttu-id="1593b-241">该示例包括`Catch`语句的几种例外情况之外，按从最特定到最常见。</span><span class="sxs-lookup"><span data-stu-id="1593b-241">The example includes `Catch` statements for several types of exceptions, ordered from the most specific to the most general.</span></span>  
  
 <span data-ttu-id="1593b-242">[!code-vb[VbVbalrStatements #&91;](../../../visual-basic/language-reference/error-messages/codesnippet/VisualBasic/try-catch-finally-statement_4.vb)]</span><span class="sxs-lookup"><span data-stu-id="1593b-242">[!code-vb[VbVbalrStatements#91](../../../visual-basic/language-reference/error-messages/codesnippet/VisualBasic/try-catch-finally-statement_4.vb)]</span></span>  
  
## <a name="example"></a><span data-ttu-id="1593b-243">示例</span><span class="sxs-lookup"><span data-stu-id="1593b-243">Example</span></span>  
 <span data-ttu-id="1593b-244">下面的示例演示如何使用`Catch When`语句筛选条件表达式。</span><span class="sxs-lookup"><span data-stu-id="1593b-244">The following example shows how to use a `Catch When` statement to filter on a conditional expression.</span></span> <span data-ttu-id="1593b-245">如果条件表达式的计算结果为`True`中的代码`Catch`块将运行。</span><span class="sxs-lookup"><span data-stu-id="1593b-245">If the conditional expression evaluates to `True`, the code in the `Catch` block runs.</span></span>  
  
 <span data-ttu-id="1593b-246">[!code-vb[VbVbalrStatements #&92;](../../../visual-basic/language-reference/error-messages/codesnippet/VisualBasic/try-catch-finally-statement_5.vb)]</span><span class="sxs-lookup"><span data-stu-id="1593b-246">[!code-vb[VbVbalrStatements#92](../../../visual-basic/language-reference/error-messages/codesnippet/VisualBasic/try-catch-finally-statement_5.vb)]</span></span>  
  
## <a name="example"></a><span data-ttu-id="1593b-247">示例</span><span class="sxs-lookup"><span data-stu-id="1593b-247">Example</span></span>  
 <span data-ttu-id="1593b-248">下面的示例有`Try…Catch`中包含的语句`Try`块。</span><span class="sxs-lookup"><span data-stu-id="1593b-248">The following example has a `Try…Catch` statement that is contained in a `Try` block.</span></span> <span data-ttu-id="1593b-249">内部`Catch`块中引发异常有其`InnerException`属性设置为原始异常。</span><span class="sxs-lookup"><span data-stu-id="1593b-249">The inner `Catch` block throws an exception that has its `InnerException` property set to the original exception.</span></span> <span data-ttu-id="1593b-250">外部`Catch`块都会报告自己的异常和内部异常。</span><span class="sxs-lookup"><span data-stu-id="1593b-250">The outer `Catch` block reports its own exception and the inner exception.</span></span>  
  
 <span data-ttu-id="1593b-251">[!code-vb[VbVbalrStatements #&93;](../../../visual-basic/language-reference/error-messages/codesnippet/VisualBasic/try-catch-finally-statement_6.vb)]</span><span class="sxs-lookup"><span data-stu-id="1593b-251">[!code-vb[VbVbalrStatements#93](../../../visual-basic/language-reference/error-messages/codesnippet/VisualBasic/try-catch-finally-statement_6.vb)]</span></span>  
  
## <a name="example"></a><span data-ttu-id="1593b-252">示例</span><span class="sxs-lookup"><span data-stu-id="1593b-252">Example</span></span>  
 <span data-ttu-id="1593b-253">下面的示例阐释异步方法的异常处理。</span><span class="sxs-lookup"><span data-stu-id="1593b-253">The following example illustrates exception handling for async methods.</span></span> <span data-ttu-id="1593b-254">若要捕获的异常，适用于异步任务，`Await`表达式是在`Try`的调用方和异常块中捕捉到`Catch`块。</span><span class="sxs-lookup"><span data-stu-id="1593b-254">To catch an exception that applies to an async task, the `Await` expression is in a `Try` block of the caller, and the exception is caught in the `Catch` block.</span></span>  
  
 <span data-ttu-id="1593b-255">在示例中取消注释 `Throw New Exception` 行以演示异常处理。</span><span class="sxs-lookup"><span data-stu-id="1593b-255">Uncomment the `Throw New Exception` line in the example to demonstrate exception handling.</span></span> <span data-ttu-id="1593b-256">中捕获到异常`Catch`阻止时，该任务的`IsFaulted`属性设置为`True`，任务的`Exception.InnerException`属性设置为异常。</span><span class="sxs-lookup"><span data-stu-id="1593b-256">The exception is caught in the `Catch` block, the task's `IsFaulted` property is set to `True`, and the task's `Exception.InnerException` property is set to the exception.</span></span>  
  
 <span data-ttu-id="1593b-257">取消注释`Throw New OperationCancelledException`行以演示当您取消异步过程中会发生什么情况。</span><span class="sxs-lookup"><span data-stu-id="1593b-257">Uncomment the `Throw New OperationCancelledException` line to demonstrate what happens when you cancel an asynchronous process.</span></span> <span data-ttu-id="1593b-258">中捕获到异常`Catch`块和任务的`IsCanceled`属性设置为`True`。</span><span class="sxs-lookup"><span data-stu-id="1593b-258">The exception is caught in the `Catch` block, and the task's `IsCanceled` property is set to `True`.</span></span> <span data-ttu-id="1593b-259">但是，在不能应用于此示例中，某些情况下`IsFaulted`设置为`True`和`IsCanceled`设置为`False`。</span><span class="sxs-lookup"><span data-stu-id="1593b-259">However, under some conditions that don't apply to this example, `IsFaulted` is set to `True` and `IsCanceled` is set to `False`.</span></span>  
  
 <span data-ttu-id="1593b-260">[!code-vb[csAsyncExceptions&#1;](../../../csharp/language-reference/keywords/codesnippet/VisualBasic/try-catch-finally-statement_7.vb)]</span><span class="sxs-lookup"><span data-stu-id="1593b-260">[!code-vb[csAsyncExceptions#1](../../../csharp/language-reference/keywords/codesnippet/VisualBasic/try-catch-finally-statement_7.vb)]</span></span>  
  
## <a name="example"></a><span data-ttu-id="1593b-261">示例</span><span class="sxs-lookup"><span data-stu-id="1593b-261">Example</span></span>  
 <span data-ttu-id="1593b-262">下面的示例阐释了在多个任务可能导致多个异常的情况中的异常处理。</span><span class="sxs-lookup"><span data-stu-id="1593b-262">The following example illustrates exception handling where multiple tasks can result in multiple exceptions.</span></span> <span data-ttu-id="1593b-263">`Try`块都有`Await`任务的表达式，<xref:System.Threading.Tasks.Task.WhenAll%2A?displayProperty=fullName>返回。</xref:System.Threading.Tasks.Task.WhenAll%2A?displayProperty=fullName></span><span class="sxs-lookup"><span data-stu-id="1593b-263">The `Try` block has the `Await` expression for the task that <xref:System.Threading.Tasks.Task.WhenAll%2A?displayProperty=fullName> returned.</span></span> <span data-ttu-id="1593b-264">当这三项任务的任务已完成<xref:System.Threading.Tasks.Task.WhenAll%2A?displayProperty=fullName>应用都已完成。</xref:System.Threading.Tasks.Task.WhenAll%2A?displayProperty=fullName></span><span class="sxs-lookup"><span data-stu-id="1593b-264">The task is complete when the three tasks to which <xref:System.Threading.Tasks.Task.WhenAll%2A?displayProperty=fullName> is applied are complete.</span></span>  
  
 <span data-ttu-id="1593b-265">三个任务中的每一个都会导致异常。</span><span class="sxs-lookup"><span data-stu-id="1593b-265">Each of the three tasks causes an exception.</span></span> <span data-ttu-id="1593b-266">`Catch`块循环访问异常，它位于`Exception.InnerExceptions`任务的属性，`Task.WhenAll`返回。</span><span class="sxs-lookup"><span data-stu-id="1593b-266">The `Catch` block iterates through the exceptions, which are found in the `Exception.InnerExceptions` property of the task that `Task.WhenAll` returned.</span></span>  
  
 <span data-ttu-id="1593b-267">[!code-vb[csAsyncExceptions&#3;](../../../csharp/language-reference/keywords/codesnippet/VisualBasic/try-catch-finally-statement_8.vb)]</span><span class="sxs-lookup"><span data-stu-id="1593b-267">[!code-vb[csAsyncExceptions#3](../../../csharp/language-reference/keywords/codesnippet/VisualBasic/try-catch-finally-statement_8.vb)]</span></span>  
  
## <a name="see-also"></a><span data-ttu-id="1593b-268">另请参阅</span><span class="sxs-lookup"><span data-stu-id="1593b-268">See Also</span></span>  
 <span data-ttu-id="1593b-269"><xref:Microsoft.VisualBasic.Information.Err%2A></xref:Microsoft.VisualBasic.Information.Err%2A></span><span class="sxs-lookup"><span data-stu-id="1593b-269"><xref:Microsoft.VisualBasic.Information.Err%2A></span></span>   
 <span data-ttu-id="1593b-270"><xref:System.Exception></xref:System.Exception></span><span class="sxs-lookup"><span data-stu-id="1593b-270"><xref:System.Exception></span></span>   
<span data-ttu-id="1593b-271"> [Exit 语句](../../../visual-basic/language-reference/statements/exit-statement.md) </span><span class="sxs-lookup"><span data-stu-id="1593b-271"> [Exit Statement](../../../visual-basic/language-reference/statements/exit-statement.md) </span></span>  
<span data-ttu-id="1593b-272"> [On Error 语句](../../../visual-basic/language-reference/statements/on-error-statement.md) </span><span class="sxs-lookup"><span data-stu-id="1593b-272"> [On Error Statement](../../../visual-basic/language-reference/statements/on-error-statement.md) </span></span>  
<span data-ttu-id="1593b-273"> [使用代码段的最佳实践](https://docs.microsoft.com/visualstudio/ide/best-practices-for-using-code-snippets) </span><span class="sxs-lookup"><span data-stu-id="1593b-273"> [Best Practices for Using Code Snippets](https://docs.microsoft.com/visualstudio/ide/best-practices-for-using-code-snippets) </span></span>  
<span data-ttu-id="1593b-274"> [异常处理](https://msdn.microsoft.com/library/dd997415) </span><span class="sxs-lookup"><span data-stu-id="1593b-274"> [Exception Handling](https://msdn.microsoft.com/library/dd997415) </span></span>  
<span data-ttu-id="1593b-275"> [Throw 语句](../../../visual-basic/language-reference/statements/throw-statement.md)</span><span class="sxs-lookup"><span data-stu-id="1593b-275"> [Throw Statement](../../../visual-basic/language-reference/statements/throw-statement.md)</span></span>
