---
title: "如何：使用 try-catch 处理异常（C# 编程指南）"
ms.date: 2015-07-20
ms.prod: .net
ms.technology:
- devlang-csharp
ms.topic: article
dev_langs:
- CSharp
helpviewer_keywords:
- exception handling [C#], try/catch blocks
- exceptions [C#], try/catch blocks
- try/catch blocks [C#]
ms.assetid: ca8e3773-980e-4767-8633-7408540e9818
caps.latest.revision: 14
author: BillWagner
ms.author: wiwagn
translation.priority.ht:
- cs-cz
- de-de
- es-es
- fr-fr
- it-it
- ja-jp
- ko-kr
- pl-pl
- pt-br
- ru-ru
- tr-tr
- zh-cn
- zh-tw
ms.translationtype: HT
ms.sourcegitcommit: 306c608dc7f97594ef6f72ae0f5aaba596c936e1
ms.openlocfilehash: f6f714cd1b652845e77405ff74fbfc860e71dc21
ms.contentlocale: zh-cn
ms.lasthandoff: 07/28/2017

---
# <a name="how-to-handle-an-exception-using-trycatch-c-programming-guide"></a><span data-ttu-id="24f27-102">如何：使用 try/catch 处理异常（C# 编程指南）</span><span class="sxs-lookup"><span data-stu-id="24f27-102">How to: Handle an Exception Using try/catch (C# Programming Guide)</span></span>
<span data-ttu-id="24f27-103">[try-catch](../../../csharp/language-reference/keywords/try-catch.md) 块的用途是捕获并处理工作代码产生的异常。</span><span class="sxs-lookup"><span data-stu-id="24f27-103">The purpose of a [try-catch](../../../csharp/language-reference/keywords/try-catch.md) block is to catch and handle an exception generated by working code.</span></span> <span data-ttu-id="24f27-104">某些异常可以在 `catch` 块中进行处理，问题得以解决并不再出现异常；但是，大多数情况下你唯一可做的是确保引发的异常是合理异常。</span><span class="sxs-lookup"><span data-stu-id="24f27-104">Some exceptions can be handled in a `catch` block and the problem solved without the exception being re-thrown; however, more often the only thing that you can do is make sure that the appropriate exception is thrown.</span></span>  
  
## <a name="example"></a><span data-ttu-id="24f27-105">示例</span><span class="sxs-lookup"><span data-stu-id="24f27-105">Example</span></span>  
 <span data-ttu-id="24f27-106">在此示例中，<xref:System.IndexOutOfRangeException> 不是最合理的异常：<xref:System.ArgumentOutOfRangeException> 对于此方法来说更有意义，因为此错误是由调用方传递的 `index` 参数引起的。</span><span class="sxs-lookup"><span data-stu-id="24f27-106">In this example, <xref:System.IndexOutOfRangeException> is not the most appropriate exception: <xref:System.ArgumentOutOfRangeException> makes more sense for the method because the error is caused by the `index` argument passed in by the caller.</span></span>  
  
 <span data-ttu-id="24f27-107">[!code-cs[csProgGuideExceptions#5](../../../csharp/programming-guide/exceptions/codesnippet/CSharp/how-to-handle-an-exception-using-try-catch_1.cs)]</span><span class="sxs-lookup"><span data-stu-id="24f27-107">[!code-cs[csProgGuideExceptions#5](../../../csharp/programming-guide/exceptions/codesnippet/CSharp/how-to-handle-an-exception-using-try-catch_1.cs)]</span></span>  
  
## <a name="comments"></a><span data-ttu-id="24f27-108">注释</span><span class="sxs-lookup"><span data-stu-id="24f27-108">Comments</span></span>  
 <span data-ttu-id="24f27-109">引发异常的代码包含在 `try` 块中。</span><span class="sxs-lookup"><span data-stu-id="24f27-109">The code that causes an exception is enclosed in the `try` block.</span></span> <span data-ttu-id="24f27-110">在此块后面紧挨着添加 `catch` 语句以处理 `IndexOutOfRangeException` 异常（如果发生此异常）。</span><span class="sxs-lookup"><span data-stu-id="24f27-110">A `catch` statement is added immediately after to handle `IndexOutOfRangeException`, if it occurs.</span></span> <span data-ttu-id="24f27-111">`catch` 块处理 `IndexOutOfRangeException` 异常并改为引发更合理的 `ArgumentOutOfRangeException` 异常。</span><span class="sxs-lookup"><span data-stu-id="24f27-111">The `catch` block handles the `IndexOutOfRangeException` and throws the more appropriate `ArgumentOutOfRangeException` exception instead.</span></span> <span data-ttu-id="24f27-112">为了向调用方提供尽可能多的信息，请考虑将原始异常指定为新异常的 <xref:System.Exception.InnerException%2A>。</span><span class="sxs-lookup"><span data-stu-id="24f27-112">In order to provide the caller with as much information as possible, consider specifying the original exception as the <xref:System.Exception.InnerException%2A> of the new exception.</span></span> <span data-ttu-id="24f27-113">因为 <xref:System.Exception.InnerException%2A> 属性为 [readonly](../../../csharp/language-reference/keywords/readonly.md)，所以必须在新异常的构造函数中指定此属性。</span><span class="sxs-lookup"><span data-stu-id="24f27-113">Because the <xref:System.Exception.InnerException%2A> property is [readonly](../../../csharp/language-reference/keywords/readonly.md), you must assign it in the constructor of the new exception.</span></span>  
  
## <a name="see-also"></a><span data-ttu-id="24f27-114">另请参阅</span><span class="sxs-lookup"><span data-stu-id="24f27-114">See Also</span></span>  
 <span data-ttu-id="24f27-115">[C# 编程指南](../../../csharp/programming-guide/index.md) </span><span class="sxs-lookup"><span data-stu-id="24f27-115">[C# Programming Guide](../../../csharp/programming-guide/index.md) </span></span>  
 <span data-ttu-id="24f27-116">[异常和异常处理](../../../csharp/programming-guide/exceptions/index.md) </span><span class="sxs-lookup"><span data-stu-id="24f27-116">[Exceptions and Exception Handling](../../../csharp/programming-guide/exceptions/index.md) </span></span>  
 [<span data-ttu-id="24f27-117">异常处理</span><span class="sxs-lookup"><span data-stu-id="24f27-117">Exception Handling</span></span>](../../../csharp/programming-guide/exceptions/exception-handling.md)

